experimentalAnalysis/hash_rb_Experimental/test-f1-1.txt
10000
buy 89
buy 91
buy 74
buy 70
buy 58
buy 65
buy 73
buy 81
buy 96
buy 83
buy 91
buy 79
buy 61
buy 76
buy 53
buy 58
buy 76
buy 86
buy 72
buy 51
buy 61
buy 83
buy 94
buy 77
buy 62
buy 60
buy 86
buy 93
buy 86
buy 71
buy 66
buy 62
buy 76
buy 84
buy 92
buy 77
buy 66
buy 89
buy 52
buy 50
buy 54
buy 87
buy 97
buy 84
buy 58
buy 50
buy 100
buy 57
buy 77
buy 71
buy 53
buy 99
buy 64
buy 91
buy 66
buy 81
buy 59
buy 80
buy 91
buy 97
buy 53
buy 92
buy 90
buy 64
buy 86
buy 86
buy 98
buy 61
buy 86
buy 95
buy 76
buy 55
buy 52
buy 77
buy 63
buy 86
buy 67
buy 57
buy 55
buy 76
buy 74
buy 97
buy 60
buy 75
buy 68
buy 74
buy 51
buy 65
buy 57
buy 96
buy 98
buy 90
buy 72
buy 99
buy 82
buy 96
buy 74
buy 56
buy 79
buy 59
buy 65
buy 76
buy 54
buy 58
buy 54
buy 59
buy 84
buy 85
buy 62
buy 74
buy 51
buy 52
buy 70
buy 62
buy 71
buy 62
buy 76
buy 100
buy 71
buy 61
buy 80
buy 94
buy 86
buy 76
buy 83
buy 87
buy 59
buy 52
buy 60
buy 53
buy 86
buy 74
buy 74
buy 74
buy 79
buy 54
buy 72
buy 66
buy 69
buy 57
buy 92
buy 65
buy 64
buy 60
buy 59
buy 73
buy 100
buy 51
buy 65
buy 83
buy 85
buy 83
buy 89
buy 89
buy 86
buy 70
buy 74
buy 52
buy 52
buy 82
buy 96
buy 65
buy 53
buy 92
buy 90
buy 78
buy 97
buy 59
buy 58
buy 68
buy 93
buy 97
buy 72
buy 65
buy 65
buy 61
buy 94
buy 77
buy 75
buy 64
buy 53
buy 51
buy 63
buy 58
buy 72
buy 74
buy 84
buy 53
buy 74
buy 74
buy 62
buy 86
buy 63
buy 74
buy 100
buy 91
buy 74
buy 59
buy 81
buy 51
buy 79
buy 50
buy 69
buy 83
buy 86
buy 91
buy 85
buy 79
buy 54
buy 61
buy 52
buy 94
buy 82
buy 68
buy 81
buy 74
buy 85
buy 71
buy 81
buy 97
buy 59
buy 78
buy 52
buy 99
buy 67
buy 85
buy 86
buy 59
buy 66
buy 65
buy 55
buy 69
buy 62
buy 70
buy 75
buy 91
buy 57
buy 58
buy 60
buy 86
buy 64
buy 69
buy 100
buy 50
buy 56
buy 56
buy 84
buy 70
buy 100
buy 89
buy 55
buy 77
buy 80
buy 87
buy 53
buy 56
buy 61
buy 78
buy 91
buy 59
buy 73
buy 94
buy 80
buy 95
buy 52
buy 81
buy 83
buy 58
buy 62
buy 100
buy 59
buy 76
buy 50
buy 79
buy 62
buy 94
buy 66
buy 87
buy 71
buy 58
buy 72
buy 100
buy 88
buy 59
buy 77
buy 50
buy 60
buy 69
buy 91
buy 81
buy 61
buy 97
buy 99
buy 50
buy 52
buy 66
buy 84
buy 69
buy 65
buy 65
buy 84
buy 82
buy 92
buy 61
buy 97
buy 72
buy 95
buy 50
buy 95
buy 56
buy 65
buy 66
buy 76
buy 62
buy 58
buy 50
buy 79
buy 94
buy 56
buy 61
buy 88
buy 97
buy 53
buy 86
buy 91
buy 94
buy 60
buy 88
buy 51
buy 67
buy 92
buy 92
buy 76
buy 100
buy 66
buy 99
buy 75
buy 55
buy 95
buy 66
buy 77
buy 85
buy 59
buy 57
buy 90
buy 78
buy 50
buy 87
buy 74
buy 86
buy 95
buy 75
buy 79
buy 54
buy 88
buy 76
buy 66
buy 90
buy 54
buy 66
buy 73
buy 95
buy 81
buy 51
buy 84
buy 84
buy 64
buy 92
buy 75
buy 90
buy 83
buy 61
buy 97
buy 97
buy 87
buy 84
buy 70
buy 93
buy 77
buy 60
buy 68
buy 56
buy 62
buy 71
buy 95
buy 90
buy 60
buy 62
buy 83
buy 65
buy 76
buy 57
buy 62
buy 87
buy 60
buy 54
buy 70
buy 97
buy 91
buy 56
buy 79
buy 66
buy 60
buy 58
buy 64
buy 89
buy 90
buy 64
buy 97
buy 55
buy 93
buy 82
buy 64
buy 64
buy 54
buy 61
buy 85
buy 57
buy 57
buy 97
buy 72
buy 60
buy 80
buy 81
buy 83
buy 83
buy 70
buy 64
buy 89
buy 66
buy 74
buy 96
buy 68
buy 72
buy 60
buy 91
buy 54
buy 91
buy 85
buy 96
buy 60
buy 96
buy 50
buy 50
buy 68
buy 91
buy 82
buy 55
buy 62
buy 80
buy 66
buy 95
buy 92
buy 90
buy 76
buy 87
buy 91
buy 62
buy 65
buy 85
buy 73
buy 100
buy 63
buy 84
buy 66
buy 54
buy 66
buy 70
buy 71
buy 65
buy 76
buy 52
buy 79
buy 51
buy 82
buy 50
buy 88
buy 68
buy 98
buy 93
buy 82
buy 92
buy 97
buy 88
buy 64
buy 87
buy 52
buy 69
buy 50
buy 58
buy 74
buy 72
buy 83
buy 87
buy 82
buy 51
buy 92
buy 74
buy 58
buy 94
buy 94
buy 70
buy 80
buy 89
buy 94
buy 84
buy 91
buy 52
buy 95
buy 99
buy 54
buy 95
buy 84
buy 90
buy 74
buy 52
buy 81
buy 52
buy 69
buy 55
buy 69
buy 74
buy 60
buy 81
buy 90
buy 59
buy 71
buy 87
buy 60
buy 76
buy 65
buy 76
buy 67
buy 64
buy 57
buy 56
buy 90
buy 95
buy 71
buy 95
buy 84
buy 75
buy 75
buy 55
buy 94
buy 72
buy 86
buy 90
buy 73
buy 70
buy 64
buy 61
buy 71
buy 86
buy 71
buy 53
buy 61
buy 62
buy 89
buy 83
buy 66
buy 82
buy 86
buy 68
buy 90
buy 79
buy 50
buy 55
buy 56
buy 91
buy 56
buy 96
buy 72
buy 96
buy 65
buy 68
buy 67
buy 87
buy 96
buy 66
buy 88
buy 80
buy 56
buy 79
buy 59
buy 54
buy 52
buy 83
buy 72
buy 50
buy 53
buy 57
buy 86
buy 65
buy 97
buy 100
buy 59
buy 59
buy 97
buy 86
buy 65
buy 88
buy 88
buy 96
buy 64
buy 89
buy 90
buy 95
buy 72
buy 57
buy 83
buy 83
buy 73
buy 92
buy 59
buy 74
buy 94
buy 63
buy 50
buy 95
buy 99
buy 99
buy 68
buy 92
buy 89
buy 93
buy 80
buy 78
buy 87
buy 60
buy 81
buy 69
buy 58
buy 81
buy 65
buy 98
buy 76
buy 59
buy 68
buy 59
buy 70
buy 89
buy 75
buy 52
buy 53
buy 66
buy 76
buy 69
buy 89
buy 64
buy 87
buy 59
buy 76
buy 66
buy 100
buy 79
buy 89
buy 54
buy 70
buy 83
buy 100
buy 71
buy 50
buy 85
buy 62
buy 98
buy 98
buy 54
buy 61
buy 92
buy 50
buy 84
buy 72
buy 51
buy 87
buy 91
buy 98
buy 62
buy 62
buy 51
buy 78
buy 97
buy 93
buy 51
buy 75
buy 81
buy 51
buy 94
buy 61
buy 72
buy 100
buy 93
buy 63
buy 64
buy 92
buy 77
buy 86
buy 96
buy 81
buy 90
buy 52
buy 94
buy 84
buy 59
buy 97
buy 79
buy 52
buy 57
buy 92
buy 88
buy 82
buy 82
buy 59
buy 65
buy 59
buy 51
buy 60
buy 86
buy 85
buy 92
buy 72
buy 84
buy 100
buy 73
buy 78
buy 55
buy 94
buy 57
buy 67
buy 76
buy 58
buy 80
buy 98
buy 70
buy 60
buy 95
buy 98
buy 83
buy 53
buy 100
buy 67
buy 94
buy 71
buy 91
buy 60
buy 93
buy 61
buy 52
buy 65
buy 57
buy 86
buy 89
buy 83
buy 81
buy 85
buy 88
buy 94
buy 75
buy 71
buy 57
buy 88
buy 80
buy 55
buy 91
buy 100
buy 64
buy 80
buy 81
buy 57
buy 78
buy 85
buy 95
buy 87
buy 72
buy 50
buy 73
buy 86
buy 63
buy 90
buy 63
buy 77
buy 70
buy 50
buy 90
buy 98
buy 100
buy 57
buy 55
buy 64
buy 72
buy 92
buy 87
buy 93
buy 91
buy 73
buy 72
buy 79
buy 86
buy 51
buy 50
buy 84
buy 51
buy 82
buy 91
buy 58
buy 93
buy 81
buy 85
buy 96
buy 50
buy 75
buy 78
buy 80
buy 60
buy 96
buy 71
buy 67
buy 89
buy 76
buy 85
buy 64
buy 58
buy 93
buy 100
buy 62
buy 98
buy 67
buy 87
buy 52
buy 65
buy 71
buy 62
buy 66
buy 96
buy 80
buy 75
buy 66
buy 66
buy 72
buy 56
buy 58
buy 77
buy 74
buy 50
buy 50
buy 88
buy 51
buy 50
buy 58
buy 100
buy 66
buy 51
buy 83
buy 80
buy 84
buy 87
buy 69
buy 74
buy 90
buy 84
buy 89
buy 54
buy 96
buy 69
buy 81
buy 92
buy 91
buy 60
buy 63
buy 96
buy 72
buy 76
buy 51
buy 77
buy 76
buy 76
buy 97
buy 64
buy 75
buy 71
buy 87
buy 82
buy 68
buy 77
buy 81
buy 79
buy 93
buy 57
buy 57
buy 93
buy 55
buy 81
buy 78
buy 60
buy 52
buy 79
buy 53
buy 84
buy 97
buy 60
buy 87
buy 63
buy 88
buy 60
buy 95
buy 50
buy 72
buy 93
buy 67
buy 90
buy 86
buy 75
buy 76
buy 62
buy 95
buy 79
buy 79
buy 82
buy 96
buy 89
buy 60
buy 89
buy 57
buy 63
buy 82
buy 84
buy 51
buy 92
buy 60
buy 82
buy 81
buy 59
buy 72
buy 94
buy 100
buy 60
buy 68
buy 50
buy 74
buy 93
buy 96
buy 70
buy 98
buy 80
buy 57
buy 60
buy 64
buy 93
buy 69
buy 61
buy 100
buy 70
buy 54
buy 98
buy 90
buy 88
buy 93
buy 71
buy 51
buy 99
buy 50
buy 50
buy 71
buy 79
buy 52
buy 62
buy 87
buy 76
buy 65
buy 69
buy 79
buy 84
buy 78
buy 64
buy 97
buy 80
buy 58
buy 58
buy 55
buy 60
buy 64
buy 51
buy 68
buy 79
buy 72
buy 62
buy 73
buy 65
buy 58
buy 99
buy 91
buy 59
buy 74
buy 72
buy 59
buy 74
buy 67
buy 88
buy 72
buy 57
buy 57
buy 76
buy 77
buy 70
buy 69
buy 65
buy 73
buy 71
buy 51
buy 87
buy 94
buy 53
buy 54
buy 89
buy 77
buy 63
buy 53
buy 92
buy 76
buy 79
buy 83
buy 53
buy 64
buy 59
buy 75
buy 87
buy 81
buy 57
buy 61
buy 63
buy 92
buy 69
buy 89
buy 66
buy 57
buy 65
buy 60
buy 78
buy 51
buy 56
buy 96
buy 50
buy 63
buy 68
buy 83
buy 98
buy 81
buy 90
buy 86
buy 94
buy 79
buy 52
buy 96
buy 53
buy 89
buy 74
buy 67
buy 92
buy 77
buy 73
buy 51
buy 86
buy 65
buy 89
buy 60
buy 72
buy 95
buy 75
buy 98
buy 89
buy 53
buy 79
buy 93
buy 66
buy 93
buy 85
buy 80
buy 73
buy 82
buy 54
buy 70
buy 72
buy 97
buy 56
buy 55
buy 80
buy 53
buy 86
buy 73
buy 76
buy 55
buy 70
buy 59
buy 93
buy 71
buy 54
buy 58
buy 60
buy 59
buy 97
buy 83
buy 74
buy 93
buy 88
buy 99
buy 69
buy 90
buy 83
buy 60
buy 74
buy 77
buy 95
buy 87
buy 60
buy 83
buy 84
buy 54
buy 53
buy 73
buy 55
buy 52
buy 70
buy 81
buy 85
buy 76
buy 72
buy 75
buy 68
buy 82
buy 81
buy 85
buy 89
buy 52
buy 90
buy 81
buy 62
buy 64
buy 78
buy 61
