experimentalAnalysis/hash_rb_Experimental/test-f1-2.txt
50000
buy 66
buy 50
buy 100
buy 96
buy 61
buy 60
buy 62
buy 84
buy 59
buy 61
buy 94
buy 77
buy 79
buy 70
buy 61
buy 61
buy 89
buy 76
buy 56
buy 58
buy 79
buy 65
buy 73
buy 98
buy 90
buy 54
buy 96
buy 68
buy 97
buy 85
buy 61
buy 67
buy 72
buy 94
buy 73
buy 51
buy 64
buy 86
buy 63
buy 81
buy 73
buy 75
buy 90
buy 97
buy 75
buy 65
buy 66
buy 88
buy 76
buy 68
buy 75
buy 78
buy 92
buy 79
buy 52
buy 55
buy 64
buy 94
buy 77
buy 74
buy 100
buy 86
buy 86
buy 88
buy 68
buy 87
buy 69
buy 69
buy 87
buy 86
buy 65
buy 100
buy 100
buy 78
buy 74
buy 71
buy 67
buy 51
buy 98
buy 63
buy 66
buy 66
buy 63
buy 84
buy 73
buy 56
buy 58
buy 96
buy 81
buy 93
buy 80
buy 70
buy 70
buy 80
buy 79
buy 73
buy 59
buy 69
buy 56
buy 54
buy 63
buy 96
buy 76
buy 71
buy 86
buy 56
buy 54
buy 93
buy 84
buy 86
buy 96
buy 60
buy 67
buy 90
buy 98
buy 74
buy 74
buy 50
buy 98
buy 80
buy 80
buy 91
buy 57
buy 67
buy 89
buy 83
buy 87
buy 54
buy 55
buy 90
buy 96
buy 68
buy 77
buy 72
buy 56
buy 56
buy 100
buy 57
buy 68
buy 69
buy 68
buy 86
buy 60
buy 88
buy 69
buy 61
buy 66
buy 93
buy 66
buy 99
buy 65
buy 68
buy 82
buy 94
buy 79
buy 79
buy 100
buy 96
buy 71
buy 93
buy 70
buy 69
buy 53
buy 87
buy 66
buy 78
buy 52
buy 98
buy 56
buy 93
buy 72
buy 91
buy 93
buy 95
buy 94
buy 64
buy 74
buy 73
buy 72
buy 75
buy 58
buy 58
buy 88
buy 91
buy 92
buy 55
buy 54
buy 76
buy 73
buy 68
buy 84
buy 99
buy 100
buy 98
buy 90
buy 55
buy 90
buy 64
buy 78
buy 70
buy 92
buy 90
buy 54
buy 70
buy 65
buy 66
buy 59
buy 81
buy 52
buy 99
buy 73
buy 78
buy 77
buy 54
buy 67
buy 95
buy 79
buy 78
buy 100
buy 65
buy 60
buy 63
buy 72
buy 69
buy 99
buy 71
buy 100
buy 86
buy 83
buy 53
buy 97
buy 70
buy 81
buy 92
buy 89
buy 72
buy 71
buy 72
buy 79
buy 65
buy 83
buy 58
buy 73
buy 59
buy 73
buy 97
buy 54
buy 50
buy 70
buy 74
buy 66
buy 81
buy 85
buy 78
buy 71
buy 69
buy 55
buy 84
buy 68
buy 97
buy 55
buy 82
buy 99
buy 97
buy 96
buy 54
buy 88
buy 62
buy 54
buy 70
buy 86
buy 71
buy 97
buy 56
buy 54
buy 64
buy 70
buy 50
buy 86
buy 97
buy 77
buy 81
buy 71
buy 86
buy 55
buy 52
buy 94
buy 67
buy 96
buy 60
buy 64
buy 86
buy 71
buy 94
buy 85
buy 51
buy 93
buy 50
buy 67
buy 85
buy 54
buy 60
buy 72
buy 67
buy 64
buy 76
buy 77
buy 82
buy 89
buy 71
buy 59
buy 92
buy 99
buy 70
buy 80
buy 85
buy 71
buy 79
buy 79
buy 79
buy 81
buy 57
buy 54
buy 94
buy 94
buy 77
buy 60
buy 91
buy 87
buy 63
buy 95
buy 56
buy 87
buy 53
buy 59
buy 86
buy 80
buy 90
buy 94
buy 78
buy 89
buy 72
buy 87
buy 100
buy 85
buy 100
buy 52
buy 89
buy 72
buy 89
buy 74
buy 60
buy 82
buy 56
buy 82
buy 97
buy 88
buy 93
buy 86
buy 68
buy 50
buy 56
buy 82
buy 90
buy 62
buy 89
buy 80
buy 68
buy 94
buy 61
buy 63
buy 65
buy 82
buy 96
buy 86
buy 61
buy 81
buy 70
buy 85
buy 86
buy 78
buy 80
buy 93
buy 95
buy 94
buy 63
buy 79
buy 84
buy 61
buy 53
buy 73
buy 57
buy 57
buy 59
buy 84
buy 60
buy 52
buy 83
buy 50
buy 61
buy 98
buy 84
buy 51
buy 58
buy 99
buy 76
buy 99
buy 82
buy 50
buy 93
buy 91
buy 86
buy 73
buy 72
buy 57
buy 56
buy 81
buy 91
buy 97
buy 78
buy 61
buy 79
buy 96
buy 90
buy 68
buy 78
buy 61
buy 58
buy 90
buy 89
buy 63
buy 61
buy 60
buy 66
buy 59
buy 56
buy 54
buy 85
buy 76
buy 70
buy 76
buy 78
buy 65
buy 75
buy 63
buy 75
buy 74
buy 61
buy 64
buy 54
buy 86
buy 66
buy 61
buy 81
buy 67
buy 59
buy 75
buy 54
buy 97
buy 96
buy 96
buy 85
buy 80
buy 59
buy 53
buy 84
buy 59
buy 79
buy 91
buy 85
buy 52
buy 70
buy 79
buy 75
buy 56
buy 74
buy 83
buy 59
buy 100
buy 75
buy 74
buy 82
buy 61
buy 94
buy 89
buy 92
buy 55
buy 67
buy 50
buy 61
buy 54
buy 71
buy 91
buy 73
buy 91
buy 76
buy 95
buy 62
buy 68
buy 83
buy 53
buy 79
buy 78
buy 71
buy 100
buy 99
buy 86
buy 52
buy 74
buy 59
buy 70
buy 69
buy 88
buy 78
buy 59
buy 57
buy 64
buy 57
buy 76
buy 75
buy 84
buy 56
buy 73
buy 73
buy 67
buy 58
buy 89
buy 90
buy 64
buy 88
buy 54
buy 57
buy 94
buy 51
buy 55
buy 82
buy 82
buy 63
buy 61
buy 64
buy 90
buy 66
buy 88
buy 63
buy 69
buy 82
buy 62
buy 64
buy 95
buy 85
buy 63
buy 50
buy 76
buy 53
buy 88
buy 98
buy 92
buy 57
buy 58
buy 67
buy 77
buy 62
buy 72
buy 78
buy 77
buy 66
buy 55
buy 75
buy 75
buy 62
buy 58
buy 71
buy 79
buy 88
buy 71
buy 53
buy 54
buy 52
buy 100
buy 80
buy 98
buy 75
buy 100
buy 52
buy 100
buy 91
buy 91
buy 99
buy 67
buy 88
buy 68
buy 52
buy 85
buy 61
buy 70
buy 83
buy 82
buy 72
buy 63
buy 73
buy 92
buy 92
buy 84
buy 62
buy 69
buy 97
buy 57
buy 95
buy 92
buy 55
buy 82
buy 93
buy 84
buy 68
buy 88
buy 60
buy 62
buy 53
buy 80
buy 75
buy 87
buy 53
buy 91
buy 50
buy 80
buy 51
buy 55
buy 90
buy 75
buy 91
buy 57
buy 54
buy 61
buy 91
buy 73
buy 86
buy 58
buy 62
buy 71
buy 100
buy 99
buy 63
buy 75
buy 86
buy 87
buy 50
buy 67
buy 62
buy 76
buy 59
buy 51
buy 70
buy 96
buy 61
buy 65
buy 92
buy 69
buy 62
buy 63
buy 80
buy 80
buy 77
buy 76
buy 68
buy 83
buy 83
buy 86
buy 53
buy 58
buy 68
buy 69
buy 69
buy 85
buy 58
buy 89
buy 71
buy 64
buy 73
buy 70
buy 67
buy 59
buy 61
buy 52
buy 69
buy 52
buy 64
buy 93
buy 97
buy 93
buy 86
buy 93
buy 67
buy 71
buy 58
buy 65
buy 79
buy 57
buy 64
buy 65
buy 67
buy 58
buy 99
buy 89
buy 50
buy 94
buy 94
buy 69
buy 94
buy 51
buy 93
buy 56
buy 89
buy 94
buy 85
buy 69
buy 57
buy 83
buy 94
buy 62
buy 60
buy 64
buy 70
buy 72
buy 67
buy 75
buy 65
buy 71
buy 82
buy 84
buy 70
buy 93
buy 58
buy 89
buy 56
buy 53
buy 57
buy 50
buy 87
buy 61
buy 100
buy 64
buy 51
buy 60
buy 81
buy 84
buy 99
buy 78
buy 77
buy 73
buy 76
buy 53
buy 69
buy 97
buy 71
buy 65
buy 87
buy 58
buy 85
buy 92
buy 73
buy 51
buy 73
buy 91
buy 87
buy 51
buy 68
buy 63
buy 59
buy 62
buy 94
buy 61
buy 51
buy 78
buy 100
buy 98
buy 89
buy 92
buy 62
buy 75
buy 65
buy 87
buy 55
buy 86
buy 58
buy 63
buy 62
buy 89
buy 52
buy 73
buy 57
buy 57
buy 56
buy 53
buy 84
buy 71
buy 59
buy 63
buy 78
buy 54
buy 84
buy 72
buy 94
buy 89
buy 92
buy 90
buy 81
buy 70
buy 91
buy 59
buy 58
buy 80
buy 97
buy 86
buy 71
buy 98
buy 62
buy 86
buy 51
buy 66
buy 90
buy 59
buy 91
buy 90
buy 61
buy 90
buy 88
buy 75
buy 77
buy 54
buy 58
buy 98
buy 81
buy 86
buy 69
buy 77
buy 65
buy 93
buy 80
buy 67
buy 77
buy 76
buy 78
buy 86
buy 52
buy 94
buy 87
buy 91
buy 85
buy 68
buy 94
buy 83
buy 52
buy 94
buy 62
buy 100
buy 77
buy 97
buy 60
buy 76
buy 61
buy 59
buy 64
buy 95
buy 57
buy 62
buy 90
buy 83
buy 63
buy 86
buy 67
buy 70
buy 94
buy 63
buy 92
buy 77
buy 79
buy 51
buy 64
buy 52
buy 84
buy 83
buy 88
buy 57
buy 100
buy 99
buy 53
buy 92
buy 94
buy 100
buy 84
buy 71
buy 66
buy 98
buy 89
buy 72
buy 74
buy 52
buy 63
buy 52
buy 72
buy 54
buy 55
buy 65
buy 71
buy 94
buy 85
buy 55
buy 83
buy 59
buy 91
buy 50
buy 81
buy 58
buy 64
buy 68
buy 64
buy 78
buy 52
buy 80
buy 51
buy 84
buy 84
buy 67
buy 75
buy 73
buy 70
buy 93
buy 98
buy 76
buy 85
buy 98
buy 72
buy 99
buy 82
buy 82
buy 67
buy 60
buy 61
buy 84
buy 90
buy 85
buy 75
buy 89
buy 80
buy 80
buy 95
buy 93
buy 89
buy 75
buy 68
buy 98
buy 97
buy 66
buy 51
buy 78
buy 78
buy 97
buy 99
buy 54
buy 83
buy 73
buy 66
buy 51
buy 57
buy 89
buy 71
buy 66
buy 58
buy 61
buy 56
buy 60
buy 77
buy 66
buy 51
buy 65
buy 98
buy 68
buy 58
buy 60
buy 94
buy 85
buy 94
buy 56
buy 99
buy 93
buy 93
buy 63
buy 77
buy 86
buy 73
buy 82
buy 85
buy 50
buy 73
buy 97
buy 85
buy 97
buy 50
buy 66
buy 69
buy 91
buy 60
buy 96
buy 67
buy 64
buy 57
buy 75
buy 65
buy 50
buy 61
buy 70
buy 93
buy 99
buy 53
buy 91
buy 87
buy 89
buy 95
buy 65
buy 82
buy 50
buy 91
buy 73
buy 78
buy 82
buy 80
buy 67
buy 52
buy 59
buy 98
buy 83
buy 84
buy 53
buy 100
buy 58
buy 84
buy 57
buy 69
buy 50
buy 56
buy 71
buy 56
buy 53
buy 85
buy 72
buy 96
buy 89
buy 68
buy 52
buy 98
buy 96
buy 68
buy 77
buy 100
buy 81
buy 64
buy 71
buy 70
buy 69
buy 59
buy 76
buy 67
buy 92
buy 96
buy 61
buy 66
buy 60
buy 95
buy 100
buy 83
buy 91
buy 50
buy 50
buy 50
buy 74
buy 57
buy 97
buy 59
buy 76
buy 72
buy 94
buy 87
buy 74
buy 54
buy 82
buy 98
buy 63
buy 65
buy 96
buy 62
buy 63
buy 93
buy 60
buy 69
buy 68
buy 57
buy 89
buy 51
buy 80
buy 100
buy 78
buy 85
buy 73
buy 91
buy 52
buy 82
buy 89
buy 57
buy 79
buy 57
buy 82
buy 96
buy 97
buy 86
buy 53
buy 92
buy 81
buy 98
buy 70
buy 59
buy 97
buy 99
buy 81
buy 82
buy 71
buy 69
buy 76
buy 81
buy 64
buy 83
buy 73
buy 65
buy 91
buy 78
buy 95
buy 52
buy 79
buy 65
buy 68
